<?xml version="1.0"?>
<robot xmlns:xacro="http://www.ros.org/wiki/xacro" >
    
    <xacro:include filename="inertial_macros.xacro" />
    <material name="white">
        <color rgba = "1 1 1 1" />
    </material>
    <material name="orange">
        <color rgba = "1 0.3 0.1 1" />
    </material>
    <material name="blue">
        <color rgba = "0.2 0.2 1 1" />
    </material>
    <material name="black">
        <color rgba = "0 0 0 1" />
    </material>
    <material name="red">
        <color rgba = "1 0 0 1" />
    </material>
    <material name="green">
        <color rgba="0.0 1.0 0.0 1.0"/>
    </material>

    
    <link name="base_link" >
    
    </link>
    <!-- BASE_FOOTPRINT LINK necessary for slam_toolbox-->

    <joint name="base_footprint_joint" type="fixed">
        <origin xyz="0.0 0.0 0.0" rpy="0.0 0.0 0.0"/>
        <parent link="base_link"/>
        <child link="base_footprint"/>
    </joint>

    <link name="base_footprint">
    </link>
    
    <!-- CHASSIS LINK -->
    <joint name = "chassis_joint" type = "fixed">
        <parent link = "base_link" />
        <child link = "chassis" />
        <origin xyz = "0 0 0" />         <!-- "-0.1 0 0" -->
    </joint>

    <link name="chassis" >
        <visual>
            <origin xyz = "0.2 0 0.075" />
            <geometry>
                <box size="0.4 0.2 0.15" />
            </geometry>
            <material name = "white" />

        </visual>
        <collision>
            <origin xyz = "0.2 0 0.075" />
            <geometry>
                <box size="0.4 0.2 0.15" />
            </geometry>
        </collision>
        <xacro:inertial_box mass="1.85" x="0.4" y="0.2" z="0.15">
            <origin xyz = "0.2 0 0.075" rpy = "0 0 0"/>
        </xacro:inertial_box>
    </link>

    <gazebo reference="chassis">
        <material>Gazebo/White</material>
    </gazebo>

    <!--LEFT WHEEL JOINT-->
    <joint name = "left_wheel_joint" type = "continuous">
        <parent link = "base_link" />
        <child link = "left_wheel" />
        <origin xyz = "0.05 0.121 0" rpy = "-${pi/2} 0 0" />
        <axis xyz = "0 0 1" />
    </joint>

    <link name="left_wheel" >
        <visual> 
            <geometry>
                <cylinder radius = "0.033" length = "0.026"/>
            </geometry>
            <material name = "blue" />

        </visual>
        <collision>
            
            <geometry>
                <cylinder radius = "0.033" length = "0.026"/>
            </geometry>

        </collision>
        <xacro:inertial_cylinder mass = "0.1" radius = "0.033" length = "0.026" >
            <origin xyz = "0 0 0" rpy = "0 0 0"/>
        </xacro:inertial_cylinder>
    </link>

    <gazebo reference="left_wheel">
        <material>Gazebo/Blue</material>
    </gazebo>



    <joint name = "leftiii_wheel_joint" type = "continuous">
        <parent link = "base_link" />
        <child link = "leftiii_wheel" />
        <origin xyz = "0.35 0.121 0" rpy = "-${pi/2} 0 0" />
        <axis xyz = "0 0 1" />
    </joint>
    
    <link name="leftiii_wheel" >
        <visual> 
            <geometry>
                <cylinder radius = "0.033" length = "0.026"/>
            </geometry>
            <material name = "green" />

        </visual>
        <collision>
            
            <geometry>
                <cylinder radius = "0.033" length = "0.026"/>
            </geometry>

        </collision>
        <xacro:inertial_cylinder mass = "0.1" radius = "0.033" length = "0.026" >
            <origin xyz = "0 0 0" rpy = "0 0 0"/>
        </xacro:inertial_cylinder>
    </link>

    <gazebo reference="leftiii_wheel">
        <material>Gazebo/Green</material>
    </gazebo>


    <!--RIGHT WHEELS-->

    <joint name = "right_wheel_joint" type = "continuous">
        <parent link = "base_link" />
        <child link = "right_wheel" />
        <origin xyz = "0.05 -0.121 0" rpy = "${pi/2} 0 0" />
        <axis xyz = "0 0 -1" />
    </joint>
    
    
    <link name="right_wheel" >
        <visual>
            
            <geometry>
                <cylinder radius = "0.033" length = "0.026"/>
            </geometry>
            <material name = "blue" />

        </visual>
        <collision>
            
            <geometry>
                <cylinder radius = "0.033" length = "0.026"/>
            </geometry>

        </collision>
        <xacro:inertial_cylinder mass = "0.1" radius = "0.033" length = "0.026" >
            <origin xyz = "0 0 0" rpy = "0 0 0"/>
        </xacro:inertial_cylinder>
    </link>

    <gazebo reference="right_wheel">
        <material>Gazebo/Blue</material>
    </gazebo>



    <joint name = "rightiii_wheel_joint" type = "continuous">
        <parent link = "base_link" />
        <child link = "rightiii_wheel" />
        <origin xyz = "0.35 -0.121 0" rpy = "${pi/2} 0 0" />
        <axis xyz = "0 0 -1" />
    </joint>
    
    
    <link name="rightiii_wheel" >
        <visual>
            
            <geometry>
                <cylinder radius = "0.033" length = "0.026"/>
            </geometry>
            <material name = "green" />

        </visual>
        <collision>
            
            <geometry>
                <cylinder radius = "0.033" length = "0.026"/>
            </geometry>

        </collision>
        <xacro:inertial_cylinder mass = "0.1" radius = "0.033" length = "0.026" >
            <origin xyz = "0 0 0" rpy = "0 0 0"/>
        </xacro:inertial_cylinder>
    </link>

    <gazebo reference="rightiii_wheel">
        <material>Gazebo/Green</material>
    </gazebo>

</robot>